<?xml version="1.0" encoding="utf-8"?>
<!-- =================================================================================== -->
<!-- |    This document was autogenerated by xacro from my_bot.xacro                   | -->
<!-- |    EDITING THIS FILE BY HAND IS NOT RECOMMENDED                                 | -->
<!-- =================================================================================== -->
<robot name="my_bot">
  <material name="Orange">
    <color rgba="1.0 0.54 0.22 1.0"/>
  </material>
  <material name="Black">
    <color rgba="0.0 0.0 0.0 1.0"/>
  </material>
  <material name="Gray">
    <color rgba="0.25 0.25 0.25 1.0"/>
  </material>
  <gazebo reference="base_link">
    <material>Gazebo/Orange</material>
  </gazebo>
  <gazebo reference="wheel_1_left">
    <material>Gazebo/Gray</material>
  </gazebo>
  <gazebo reference="wheel_1_left_line">
    <material>Gazebo/Black</material>
  </gazebo>
  <gazebo reference="wheel_2_left">
    <material>Gazebo/Gray</material>
  </gazebo>
  <gazebo reference="wheel_2_left_line">
    <material>Gazebo/Black</material>
  </gazebo>
  <gazebo reference="wheel_3_left">
    <material>Gazebo/Gray</material>
  </gazebo>
  <gazebo reference="wheel_3_left_line">
    <material>Gazebo/Black</material>
  </gazebo>
  <gazebo reference="wheel_1_right">
    <material>Gazebo/Gray</material>
  </gazebo>
  <gazebo reference="wheel_1_right_line">
    <material>Gazebo/Black</material>
  </gazebo>
  <gazebo reference="wheel_2_right">
    <material>Gazebo/Gray</material>
  </gazebo>
  <gazebo reference="wheel_2_right_line">
    <material>Gazebo/Black</material>
  </gazebo>
  <gazebo reference="wheel_3_right">
    <material>Gazebo/Gray</material>
  </gazebo>
  <gazebo reference="wheel_3_right_line">
    <material>Gazebo/Black</material>
  </gazebo>
  <gazebo reference="left_shoulder_link">
    <material>Gazebo/Gray</material>
  </gazebo>
  <gazebo reference="left_shoulder_forward_link">
    <material>Gazebo/Orange</material>
  </gazebo>
  <gazebo reference="left_upper_arm_link">
    <material>Gazebo/Orange</material>
  </gazebo>
  <gazebo reference="left_center_link">
    <material>Gazebo/Gray</material>
  </gazebo>
  <gazebo reference="left_hand_link">
    <material>Gazebo/Gray</material>
  </gazebo>
  <gazebo reference="right_shoulder_link">
    <material>Gazebo/Gray</material>
  </gazebo>
  <gazebo reference="right_shoulder_forward_link">
    <material>Gazebo/Orange</material>
  </gazebo>
  <gazebo reference="right_upper_arm_link">
    <material>Gazebo/Orange</material>
  </gazebo>
  <gazebo reference="right_center_link">
    <material>Gazebo/Gray</material>
  </gazebo>
  <gazebo reference="right_hand_link">
    <material>Gazebo/Gray</material>
  </gazebo>
  <gazebo reference="neck_link">
    <material>Gazebo/Orange</material>
  </gazebo>
  <gazebo reference="left_ocular_link">
    <material>Gazebo/Orange</material>
  </gazebo>
  <gazebo reference="left_eye_link">
    <material>Gazebo/Black</material>
  </gazebo>
  <gazebo reference="right_ocular_link">
    <material>Gazebo/Orange</material>
  </gazebo>
  <gazebo reference="right_eye_link">
    <material>Gazebo/Black</material>
  </gazebo>
  <!-- * * * Link Definitions * * * -->
  <link name="base_link">
    <visual>
      <origin rpy="0 0 0" xyz="0 0 0.3"/>
      <geometry>
        <box size="0.6 0.6 0.6"/>
      </geometry>
    </visual>
    <collision>
      <geometry>
        <box size="0.6 0.6 0.6"/>
      </geometry>
    </collision>
    <inertial>
      <mass value="2"/>
      <inertia ixx="1" ixy="0.0" ixz="0.0" iyy="1" iyz="0.0" izz="1"/>
    </inertial>
  </link>
  <link name="wheel_1_left">
    <visual>
      <origin rpy="1.57 0 0" xyz="0 0 0"/>
      <geometry>
        <cylinder length="0.08" radius="0.125"/>
      </geometry>
    </visual>
    <collision>
      <geometry>
        <cylinder length="0.08" radius="0.125"/>
      </geometry>
    </collision>
    <inertial>
      <mass value="0.7"/>
      <inertia ixx="1" ixy="0.0" ixz="0.0" iyy="1" iyz="0.0" izz="1"/>
    </inertial>
  </link>
  <link name="wheel_1_left_line">
    <visual>
      <origin rpy="0 0 0" xyz="0 0 0"/>
      <geometry>
        <box size="0.01 0.01 0.2"/>
      </geometry>
    </visual>
    <collision>
      <geometry>
        <box size="0.01 0.01 0.2"/>
      </geometry>
    </collision>
    <inertial>
      <mass value="0.001"/>
      <inertia ixx="1" ixy="0.0" ixz="0.0" iyy="1" iyz="0.0" izz="1"/>
    </inertial>
  </link>
  <link name="wheel_2_left">
    <visual>
      <origin rpy="1.57 0 0" xyz="0 0 0"/>
      <geometry>
        <cylinder length="0.08" radius="0.125"/>
      </geometry>
    </visual>
    <collision>
      <geometry>
        <cylinder length="0.08" radius="0.125"/>
      </geometry>
    </collision>
    <inertial>
      <mass value="0.7"/>
      <inertia ixx="1" ixy="0.0" ixz="0.0" iyy="1" iyz="0.0" izz="1"/>
    </inertial>
  </link>
  <link name="wheel_2_left_line">
    <visual>
      <origin rpy="0 0 0" xyz="0 0 0"/>
      <geometry>
        <box size="0.01 0.01 0.2"/>
      </geometry>
    </visual>
    <collision>
      <geometry>
        <box size="0.01 0.01 0.2"/>
      </geometry>
    </collision>
    <inertial>
      <mass value="0.001"/>
      <inertia ixx="1" ixy="0.0" ixz="0.0" iyy="1" iyz="0.0" izz="1"/>
    </inertial>
  </link>
  <link name="wheel_3_left">
    <visual>
      <origin rpy="1.57 0 0" xyz="0 0 0"/>
      <geometry>
        <cylinder length="0.08" radius="0.125"/>
      </geometry>
    </visual>
    <collision>
      <geometry>
        <cylinder length="0.08" radius="0.125"/>
      </geometry>
    </collision>
    <inertial>
      <mass value="0.7"/>
      <inertia ixx="1" ixy="0.0" ixz="0.0" iyy="1" iyz="0.0" izz="1"/>
    </inertial>
  </link>
  <link name="wheel_3_left_line">
    <visual>
      <origin rpy="0 0 0" xyz="0 0 0"/>
      <geometry>
        <box size="0.01 0.01 0.2"/>
      </geometry>
    </visual>
    <collision>
      <geometry>
        <box size="0.01 0.01 0.2"/>
      </geometry>
    </collision>
    <inertial>
      <mass value="0.001"/>
      <inertia ixx="1" ixy="0.0" ixz="0.0" iyy="1" iyz="0.0" izz="1"/>
    </inertial>
  </link>
  <link name="wheel_1_right">
    <visual>
      <origin rpy="1.57 0 0" xyz="0 0 0"/>
      <geometry>
        <cylinder length="0.08" radius="0.125"/>
      </geometry>
    </visual>
    <collision>
      <geometry>
        <cylinder length="0.08" radius="0.125"/>
      </geometry>
    </collision>
    <inertial>
      <mass value="0.7"/>
      <inertia ixx="1" ixy="0.0" ixz="0.0" iyy="1" iyz="0.0" izz="1"/>
    </inertial>
  </link>
  <link name="wheel_1_right_line">
    <visual>
      <origin rpy="0 0 0" xyz="0 0 0"/>
      <geometry>
        <box size="0.01 0.01 0.2"/>
      </geometry>
    </visual>
    <collision>
      <geometry>
        <box size="0.01 0.01 0.2"/>
      </geometry>
    </collision>
    <inertial>
      <mass value="0.001"/>
      <inertia ixx="1" ixy="0.0" ixz="0.0" iyy="1" iyz="0.0" izz="1"/>
    </inertial>
  </link>
  <link name="wheel_2_right">
    <visual>
      <origin rpy="1.57 0 0" xyz="0 0 0"/>
      <geometry>
        <cylinder length="0.08" radius="0.125"/>
      </geometry>
    </visual>
    <collision>
      <geometry>
        <cylinder length="0.08" radius="0.125"/>
      </geometry>
    </collision>
    <inertial>
      <mass value="0.7"/>
      <inertia ixx="1" ixy="0.0" ixz="0.0" iyy="1" iyz="0.0" izz="1"/>
    </inertial>
  </link>
  <link name="wheel_2_right_line">
    <visual>
      <origin rpy="0 0 0" xyz="0 0 0"/>
      <geometry>
        <box size="0.01 0.01 0.2"/>
      </geometry>
    </visual>
    <collision>
      <geometry>
        <box size="0.01 0.01 0.2"/>
      </geometry>
    </collision>
    <inertial>
      <mass value="0.001"/>
      <inertia ixx="1" ixy="0.0" ixz="0.0" iyy="1" iyz="0.0" izz="1"/>
    </inertial>
  </link>
  <link name="wheel_3_right">
    <visual>
      <origin rpy="1.57 0 0" xyz="0 0 0"/>
      <geometry>
        <cylinder length="0.08" radius="0.125"/>
      </geometry>
    </visual>
    <collision>
      <geometry>
        <cylinder length="0.08" radius="0.125"/>
      </geometry>
    </collision>
    <inertial>
      <mass value="0.7"/>
      <inertia ixx="1" ixy="0.0" ixz="0.0" iyy="1" iyz="0.0" izz="1"/>
    </inertial>
  </link>
  <link name="wheel_3_right_line">
    <visual>
      <origin rpy="0 0 0" xyz="0 0 0"/>
      <geometry>
        <box size="0.01 0.01 0.2"/>
      </geometry>
    </visual>
    <collision>
      <geometry>
        <box size="0.01 0.01 0.2"/>
      </geometry>
    </collision>
    <inertial>
      <mass value="0.001"/>
      <inertia ixx="1" ixy="0.0" ixz="0.0" iyy="1" iyz="0.0" izz="1"/>
    </inertial>
  </link>
  <link name="left_shoulder_link">
    <visual>
      <origin rpy="0 0 0" xyz="0 0 0"/>
      <geometry>
        <box size="0.025 0.02 0.05"/>
      </geometry>
    </visual>
    <collision>
      <geometry>
        <box size="0.025 0.02 0.05"/>
      </geometry>
    </collision>
    <inertial>
      <mass value="0.2"/>
      <inertia ixx="1" ixy="0.0" ixz="0.0" iyy="1" iyz="0.0" izz="1"/>
    </inertial>
  </link>
  <link name="left_shoulder_forward_link">
    <visual>
      <origin rpy="0 0 0" xyz="0 0 0"/>
      <geometry>
        <box size="0.05 0.07 0.05"/>
      </geometry>
    </visual>
    <collision>
      <geometry>
        <box size="0.05 0.07 0.05"/>
      </geometry>
    </collision>
    <inertial>
      <mass value="0.4"/>
      <inertia ixx="1" ixy="0.0" ixz="0.0" iyy="1" iyz="0.0" izz="1"/>
    </inertial>
  </link>
  <link name="left_upper_arm_link">
    <visual>
      <origin rpy="0 0 0" xyz="0 0 0"/>
      <geometry>
        <cylinder length="0.4" radius="0.03"/>
      </geometry>
    </visual>
    <collision>
      <geometry>
        <cylinder length="0.4" radius="0.03"/>
      </geometry>
    </collision>
    <inertial>
      <mass value="1"/>
      <inertia ixx="1" ixy="0.0" ixz="0.0" iyy="1" iyz="0.0" izz="1"/>
    </inertial>
  </link>
  <link name="left_center_link">
    <visual>
      <origin rpy="0 0 1.57" xyz="0 0 0"/>
      <geometry>
        <box size="0.06 0.08 0.01"/>
      </geometry>
    </visual>
    <collision>
      <geometry>
        <box size="0.06 0.08 0.01"/>
      </geometry>
    </collision>
    <inertial>
      <mass value="0.1"/>
      <inertia ixx="1" ixy="0.0" ixz="0.0" iyy="1" iyz="0.0" izz="1"/>
    </inertial>
  </link>
  <link name="left_hand_link">
    <visual>
      <origin rpy="0 0 0" xyz="0 0 0"/>
      <geometry>
        <box size="0.11 0.01 0.15"/>
      </geometry>
    </visual>
    <collision>
      <geometry>
        <box size="0.11 0.01 0.15"/>
      </geometry>
    </collision>
    <inertial>
      <mass value="0.3"/>
      <inertia ixx="1" ixy="0.0" ixz="0.0" iyy="1" iyz="0.0" izz="1"/>
    </inertial>
  </link>
  <link name="right_shoulder_link">
    <visual>
      <origin rpy="0 0 0" xyz="0 0 0"/>
      <geometry>
        <box size="0.025 0.02 0.05"/>
      </geometry>
    </visual>
    <collision>
      <geometry>
        <box size="0.025 0.02 0.05"/>
      </geometry>
    </collision>
    <inertial>
      <mass value="0.2"/>
      <inertia ixx="1" ixy="0.0" ixz="0.0" iyy="1" iyz="0.0" izz="1"/>
    </inertial>
  </link>
  <link name="right_shoulder_forward_link">
    <visual>
      <origin rpy="0 0 0" xyz="0 0 0"/>
      <geometry>
        <box size="0.05 0.07 0.05"/>
      </geometry>
    </visual>
    <collision>
      <geometry>
        <box size="0.05 0.07 0.05"/>
      </geometry>
    </collision>
    <inertial>
      <mass value="0.4"/>
      <inertia ixx="1" ixy="0.0" ixz="0.0" iyy="1" iyz="0.0" izz="1"/>
    </inertial>
  </link>
  <link name="right_upper_arm_link">
    <visual>
      <origin rpy="0 0 0" xyz="0 0 0"/>
      <geometry>
        <cylinder length="0.4" radius="0.03"/>
      </geometry>
    </visual>
    <collision>
      <geometry>
        <cylinder length="0.4" radius="0.03"/>
      </geometry>
    </collision>
    <inertial>
      <mass value="1"/>
      <inertia ixx="1" ixy="0.0" ixz="0.0" iyy="1" iyz="0.0" izz="1"/>
    </inertial>
  </link>
  <link name="right_center_link">
    <visual>
      <origin rpy="0 0 1.57" xyz="0 0 0"/>
      <geometry>
        <box size="0.06 0.08 0.01"/>
      </geometry>
    </visual>
    <collision>
      <geometry>
        <box size="0.06 0.08 0.01"/>
      </geometry>
    </collision>
    <inertial>
      <mass value="0.1"/>
      <inertia ixx="1" ixy="0.0" ixz="0.0" iyy="1" iyz="0.0" izz="1"/>
    </inertial>
  </link>
  <link name="right_hand_link">
    <visual>
      <origin rpy="0 0 0" xyz="0 0 0"/>
      <geometry>
        <box size="0.11 0.01 0.15"/>
      </geometry>
    </visual>
    <collision>
      <geometry>
        <box size="0.11 0.01 0.15"/>
      </geometry>
    </collision>
    <inertial>
      <mass value="0.3"/>
      <inertia ixx="1" ixy="0.0" ixz="0.0" iyy="1" iyz="0.0" izz="1"/>
    </inertial>
  </link>
  <link name="neck_link">
    <visual>
      <origin rpy="0 0 0" xyz="0 0 0"/>
      <geometry>
        <cylinder length="0.2" radius="0.05"/>
      </geometry>
    </visual>
    <collision>
      <geometry>
        <cylinder length="0.2" radius="0.05"/>
      </geometry>
    </collision>
    <inertial>
      <mass value="0.2"/>
      <inertia ixx="1" ixy="0.0" ixz="0.0" iyy="1" iyz="0.0" izz="1"/>
    </inertial>
  </link>
  <link name="left_ocular_link">
    <visual>
      <origin rpy="0 1.57 0" xyz="0 0 0"/>
      <geometry>
        <cylinder length="0.2" radius="0.08"/>
      </geometry>
    </visual>
    <collision>
      <geometry>
        <cylinder length="0.2" radius="0.08"/>
      </geometry>
    </collision>
    <inertial>
      <mass value="0.1"/>
      <inertia ixx="1" ixy="0.0" ixz="0.0" iyy="1" iyz="0.0" izz="1"/>
    </inertial>
  </link>
  <link name="left_eye_link">
    <visual>
      <origin rpy="0 1.57 0" xyz="0 0 0"/>
      <geometry>
        <cylinder length="0.01" radius="0.0533333333333"/>
      </geometry>
    </visual>
    <collision>
      <geometry>
        <cylinder length="0.01" radius="0.0533333333333"/>
      </geometry>
    </collision>
    <inertial>
      <mass value="0.001"/>
      <inertia ixx="1" ixy="0.0" ixz="0.0" iyy="1" iyz="0.0" izz="1"/>
    </inertial>
  </link>
  <link name="right_ocular_link">
    <visual>
      <origin rpy="0 1.57 0" xyz="0 0 0"/>
      <geometry>
        <cylinder length="0.2" radius="0.08"/>
      </geometry>
    </visual>
    <collision>
      <geometry>
        <cylinder length="0.2" radius="0.08"/>
      </geometry>
    </collision>
    <inertial>
      <mass value="0.1"/>
      <inertia ixx="1" ixy="0.0" ixz="0.0" iyy="1" iyz="0.0" izz="1"/>
    </inertial>
  </link>
  <link name="right_eye_link">
    <visual>
      <origin rpy="0 1.57 0" xyz="0 0 0"/>
      <geometry>
        <cylinder length="0.01" radius="0.0533333333333"/>
      </geometry>
    </visual>
    <collision>
      <geometry>
        <cylinder length="0.01" radius="0.0533333333333"/>
      </geometry>
    </collision>
    <inertial>
      <mass value="0.001"/>
      <inertia ixx="1" ixy="0.0" ixz="0.0" iyy="1" iyz="0.0" izz="1"/>
    </inertial>
  </link>
  <!-- * * * Joint Definitions * * * -->
  <joint name="wheel_1_left_joint" type="continuous">
    <parent link="base_link"/>
    <child link="wheel_1_left"/>
    <origin rpy="0 0 0" xyz="0.25 0.34 0"/>
    <axis xyz="0 1 0"/>
  </joint>
  <joint name="wheel_1_left_line_joint" type="fixed">
    <parent link="wheel_1_left"/>
    <child link="wheel_1_left_line"/>
    <origin rpy="0 0 0" xyz="0 0.04 0"/>
  </joint>
  <joint name="wheel_2_left_joint" type="continuous">
    <parent link="base_link"/>
    <child link="wheel_2_left"/>
    <origin rpy="0 0 0" xyz="0 0.34 0"/>
    <axis xyz="0 1 0"/>
  </joint>
  <joint name="wheel_2_left_line_joint" type="fixed">
    <parent link="wheel_2_left"/>
    <child link="wheel_2_left_line"/>
    <origin rpy="0 0 0" xyz="0 0.04 0"/>
  </joint>
  <joint name="wheel_3_left_joint" type="continuous">
    <parent link="base_link"/>
    <child link="wheel_3_left"/>
    <origin rpy="0 0 0" xyz="-0.25 0.34 0"/>
    <axis xyz="0 1 0"/>
  </joint>
  <joint name="wheel_3_left_line_joint" type="fixed">
    <parent link="wheel_3_left"/>
    <child link="wheel_3_left_line"/>
    <origin rpy="0 0 0" xyz="0 0.04 0"/>
  </joint>
  <joint name="wheel_1_right_joint" type="continuous">
    <parent link="base_link"/>
    <child link="wheel_1_right"/>
    <origin rpy="0 0 0" xyz="0.25 -0.34 0"/>
    <axis xyz="0 1 0"/>
  </joint>
  <joint name="wheel_1_right_line_joint" type="fixed">
    <parent link="wheel_1_right"/>
    <child link="wheel_1_right_line"/>
    <origin rpy="0 0 0" xyz="0 -0.04 0"/>
  </joint>
  <joint name="wheel_2_right_joint" type="continuous">
    <parent link="base_link"/>
    <child link="wheel_2_right"/>
    <origin rpy="0 0 0" xyz="0 -0.34 0"/>
    <axis xyz="0 1 0"/>
  </joint>
  <joint name="wheel_2_right_line_joint" type="fixed">
    <parent link="wheel_2_right"/>
    <child link="wheel_2_right_line"/>
    <origin rpy="0 0 0" xyz="0 -0.04 0"/>
  </joint>
  <joint name="wheel_3_right_joint" type="continuous">
    <parent link="base_link"/>
    <child link="wheel_3_right"/>
    <origin rpy="0 0 0" xyz="-0.25 -0.34 0"/>
    <axis xyz="0 1 0"/>
  </joint>
  <joint name="wheel_3_right_line_joint" type="fixed">
    <parent link="wheel_3_right"/>
    <child link="wheel_3_right_line"/>
    <origin rpy="0 0 0" xyz="0 -0.04 0"/>
  </joint>
  <joint name="left_shoulder_joint" type="fixed">
    <parent link="base_link"/>
    <child link="left_shoulder_link"/>
    <origin rpy="0 0 0" xyz="0 0.31 0.4"/>
  </joint>
  <joint name="left_shoulder_forward_joint" type="revolute">
    <parent link="left_shoulder_link"/>
    <child link="left_shoulder_forward_link"/>
    <origin rpy="0 0 0" xyz="0 0.045 0"/>
    <limit effort="10" lower="-1.57" upper="1.57" velocity="3"/>
    <axis xyz="0 1 0"/>
  </joint>
  <joint name="left_upper_arm_joint" type="fixed">
    <parent link="left_shoulder_forward_link"/>
    <child link="left_upper_arm_link"/>
    <origin rpy="0 1.57 0" xyz="0.225 0 0"/>
  </joint>
  <joint name="left_center_joint" type="revolute">
    <parent link="left_upper_arm_link"/>
    <child link="left_center_link"/>
    <origin rpy="0 0 1.57" xyz="0 0 0.205"/>
    <limit effort="10" lower="-1.57" upper="1.57" velocity="3"/>
    <axis xyz="0 0 1"/>
  </joint>
  <joint name="left_hand_joint" type="fixed">
    <parent link="left_center_link"/>
    <child link="left_hand_link"/>
    <origin rpy="0 0 0" xyz="0 0 0.08"/>
  </joint>
  <joint name="right_shoulder_joint" type="fixed">
    <parent link="base_link"/>
    <child link="right_shoulder_link"/>
    <origin rpy="0 0 0" xyz="0 -0.31 0.4"/>
  </joint>
  <joint name="right_shoulder_forward_joint" type="revolute">
    <parent link="right_shoulder_link"/>
    <child link="right_shoulder_forward_link"/>
    <origin rpy="0 0 0" xyz="0 -0.045 0"/>
    <limit effort="10" lower="-1.57" upper="1.57" velocity="3"/>
    <axis xyz="0 1 0"/>
  </joint>
  <joint name="right_upper_arm_joint" type="fixed">
    <parent link="right_shoulder_forward_link"/>
    <child link="right_upper_arm_link"/>
    <origin rpy="0 1.57 0" xyz="0.225 0 0"/>
  </joint>
  <joint name="right_center_joint" type="revolute">
    <parent link="right_upper_arm_link"/>
    <child link="right_center_link"/>
    <origin rpy="0 0 1.57" xyz="0 0 0.205"/>
    <limit effort="10" lower="-1.57" upper="1.57" velocity="3"/>
    <axis xyz="0 0 1"/>
  </joint>
  <joint name="right_hand_joint" type="fixed">
    <parent link="right_center_link"/>
    <child link="right_hand_link"/>
    <origin rpy="0 0 0" xyz="0 0 0.08"/>
  </joint>
  <joint name="neck_joint" type="revolute">
    <parent link="base_link"/>
    <child link="neck_link"/>
    <origin rpy="0 0 0" xyz="0 0 0.7"/>
    <limit effort="10" lower="-1.57" upper="1.57" velocity="3"/>
    <axis xyz="0 0 1"/>
  </joint>
  <joint name="left_ocular_joint" type="fixed">
    <parent link="neck_link"/>
    <child link="left_ocular_link"/>
    <origin rpy="0 0 0" xyz="0 0.07 0.16"/>
  </joint>
  <joint name="left_eye_joint" type="fixed">
    <parent link="left_ocular_link"/>
    <child link="left_eye_link"/>
    <origin rpy="0 0 0" xyz="0.1 0 0"/>
  </joint>
  <joint name="right_ocular_joint" type="fixed">
    <parent link="neck_link"/>
    <child link="right_ocular_link"/>
    <origin rpy="0 0 0" xyz="0 -0.07 0.16"/>
  </joint>
  <joint name="right_eye_joint" type="fixed">
    <parent link="right_ocular_link"/>
    <child link="right_eye_link"/>
    <origin rpy="0 0 0" xyz="0.1 0 0"/>
  </joint>
</robot>

